<?xml version="1.0"?>
<robot name="Virat" xmlns:xacro="http://www.ros.org/wiki/xacro">
<xacro:property name="damping_value" value="0.0" />
<xacro:property name="friction_value" value="0.0" />
<xacro:property name="camera_size" value="0.05"/>
<xacro:property name="camera_origin_x" value="0.73"/>
<xacro:property name="camera_origin_y" value="0"/>
<xacro:property name="camera_origin_z" value="1.18"/>
<xacro:include filename="$(find pothole_detector)/urdf/plugins.gazebo"/>
  <link name="chasis">
    <visual>
      <origin rpy="0.0 0 0" xyz="0 0 0"/>
      <geometry>
        <mesh filename="package://pothole_detector/meshes/body/bot2.dae"/>
      </geometry>
    </visual>

    <collision>
    <origin rpy="0.0 0 0" xyz="0 0 0"/>
        <geometry>
        <mesh filename="package://pothole_detector/meshes/wheels/bot2.dae"/>
        </geometry>
    </collision>

    <inertial>
      <mass value="15"/>
      <origin xyz="0.0 0 0" rpy=" 0 0 0"/>
      <inertia
          ixx="0.1" ixy="0" ixz="0"
          iyy="0.1" iyz="0"
          izz="0.1"
      />
    </inertial>
  </link>

  <joint name="leftwheel_chasis" type="continuous">
    <origin rpy="0 0 0" xyz="0 0.323 0"/>
    <parent link="chasis"/>
    <child link="leftwheel"/>
    <axis xyz="0 1 0" />
    <limit velocity="100" effort="1"/>
    <dynamics damping="${damping_value}" friction="${friction_value}"/>
  </joint>

  

  

  <link name="leftwheel">
    <visual>
      <origin rpy="0.0 0 0" xyz="0 0 0"/>
      <geometry>
        <mesh filename="package://pothole_detector/meshes/wheels/tyre1.dae"/>
      </geometry>
    </visual>

    <collision>
    <origin rpy="0.0 0 0" xyz="0 0 0"/>
        <geometry>
        <mesh filename="package://pothole_detector/meshes/wheels/tyre1.dae"/>
        </geometry>
    </collision>

    <inertial>
      <origin rpy="0.0 0 0" xyz="0 0 0"/>
      <mass value="1"/>
      <inertia
        ixx="0.1" ixy="0.0" ixz="0.0"
        iyy="0.1" iyz="0.0"
        izz="0.1"/>
    </inertial>
  </link>


  <joint name="rightwheel_chasis" type="continuous">
    <origin rpy="0 0 0" xyz="0 -0.323 0"/>
    <parent link="chasis"/>
    <child link="rightwheel"/>
    <axis xyz="0 1 0" />
    <limit velocity="100" effort="1"/>
    <dynamics damping="${damping_value}" friction="${friction_value}"/>
  </joint>

  

  

  <link name="rightwheel">
    <visual>
      <origin rpy="0.0 0 0" xyz="0 0 0"/>
      <geometry>
        <mesh filename="package://pothole_detector/meshes/wheels/tyre1.dae"/>
      </geometry>
    </visual>
    <collision>
    <origin rpy="0.0 0 0" xyz="0 0 0"/>
        <geometry>
        <mesh filename="package://pothole_detector/meshes/wheels/tyre1.dae"/>
        </geometry>
    </collision>
    <inertial>
      <origin rpy="0.0 0 0" xyz="0 0 0"/>
      <mass value="1"/>
      <inertia
        ixx="0.1" ixy="0.0" ixz="0.0"
        iyy="0.1" iyz="0.0"
        izz="0.1"/>
    </inertial>
  </link>



  <joint name="castorwheel_chasis" type="fixed">
    <origin rpy="0 0 0" xyz="0.48 0 0.02"/>
    <parent link="chasis"/>
    <child link="castor_wheel"/>
    <axis xyz="0 1 0" />
    <limit velocity="100" effort="1"/>
    <dynamics damping="${damping_value}" friction="${friction_value}"/>
  </joint>


  <link name="castor_wheel">
    <visual>
      <origin rpy="0.0 0 0" xyz="0 0 0"/>
      <geometry>
        <mesh filename="package://pothole_detector/meshes/wheels/castors1.dae"/>
      </geometry>
    </visual>
    <collision>
    <origin rpy="0.0 0 0" xyz="0 0 0"/>
        <geometry>
        <mesh filename="package://pothole_detector/meshes/wheels/castors1.dae"/>
        </geometry>
    </collision>
    <inertial>
      <origin rpy="0.0 0 0" xyz="0 0 0"/>
      <mass value="5"/>
      <inertia
        ixx="0.1" ixy="0.0" ixz="0.0"
        iyy="0.1" iyz="0.0"
        izz="0.1"/>
    </inertial>
  </link>

  
   <link name="camera">
    <visual>
      <geometry>
        <box size="${camera_size} ${camera_size} ${camera_size}"/>
      </geometry>
      <material name="blue"/>
    </visual>
    <collision>
      <geometry>
        <box size="${camera_size} ${camera_size} ${camera_size}"/>
      </geometry>
    </collision>
    <inertial>
      <mass value="0.02"/>
      <inertia ixx="1e-6" ixy="0.0" ixz="0.0" iyy="1e-6" iyz="0.0" izz="1e-6"/>
    </inertial>
  </link>

  <joint name="camera_joint" type="fixed">
    <origin xyz="${camera_origin_x} ${camera_origin_y} ${camera_origin_z}" rpy="0 0.45 0"/>
    <parent link="chasis"/>
    <child link="camera"/>
  </joint>
  <gazebo>
    <plugin filename="libgazebo_ros_diff_drive.so" name="differential_drive_controller">
      <alwaysOn>true</alwaysOn>
      <updateRate>60</updateRate>
      <leftJoint>leftwheel_chasis</leftJoint>
      <rightJoint>rightwheel_chasis</rightJoint>
      <wheelSeparation>0.646</wheelSeparation>
      <wheelDiameter>0.1</wheelDiameter>
      <torque>0.1</torque>
      <commandTopic>cmd_vel</commandTopic>
      <odometryTopic>odom</odometryTopic>
      <odometryFrame>odom</odometryFrame>
      <robotBaseFrame>chasis</robotBaseFrame>
    </plugin>
  </gazebo>
   
</robot>