<?xml version="1.0"?>
<robot name="myfirst">
  <link name="body_bot">
    <visual>
      <origin rpy="0.0 0 0" xyz="0 0 0"/>
      <geometry>
        <mesh filename="package://pothole_detector/meshes/body/bot2.dae"/>
      </geometry>
    </visual>
  </link>

  <joint name="leftwheel_chasis" type="revolute">
    <origin rpy="0 0 0" xyz="0 0.323 0"/>
    <parent link="body_bot"/>
    <child link="leftwheel"/>
    <axis xyz="0 0 1" />
    <limit upper="1.57" lower="-1.57" velocity="2" effort="1"/>
  </joint>

  

  

  <link name="leftwheel">
    <visual>
      <origin rpy="0.0 0 0" xyz="0 0.323 0"/>
      <geometry>
        <mesh filename="package://pothole_detector/meshes/wheels/tyre1.dae"/>
      </geometry>
    </visual>
  </link>


  <joint name="rightwheel_chasis" type="revolute">
    <origin rpy="0 0 0" xyz="0 -0.323 0"/>
    <parent link="body_bot"/>
    <child link="rightwheel"/>
    <axis xyz="0 0 1" />
    <limit upper="1.57" lower="-1.57" velocity="2" effort="1"/>
  </joint>

  

  

  <link name="rightwheel">
    <visual>
      <origin rpy="0.0 0 0" xyz="0 -0.323 0"/>
      <geometry>
        <mesh filename="package://pothole_detector/meshes/wheels/tyre1.dae"/>
      </geometry>
    </visual>
  </link>



  <joint name="castorwheel_chasis" type="revolute">
    <origin rpy="0 0 0" xyz="0.48 0 0.02"/>
    <parent link="body_bot"/>
    <child link="castor_wheel"/>
    <axis xyz="0 0 1" />
    <limit upper="1.57" lower="-1.57" velocity="2" effort="1"/>
  </joint>


  <link name="castor_wheel">
    <visual>
      <origin rpy="0.0 0 0" xyz="0.48 0 0.02" />
      <geometry>
        <mesh filename="package://pothole_detector/meshes/wheels/castors1.dae"/>
      </geometry>
    </visual>
  </link>