<?xml version="1.0"?>
<robot name="Virat" xmlns:xacro="http://www.ros.org/wiki/xacro">

<xacro:property name="damping_value" value="10" />
<xacro:property name="friction_value" value="0.1" />


  <link name="chasis">
    <visual>
      <origin rpy="0.0 0 0" xyz="0 0 0"/>
      <geometry>
        <mesh filename="package://pothole_detector/meshes/body/bot2.dae"/>
      </geometry>
    </visual>
    <inertial>
      <mass value="15.0"/>
      <origin xyz="0.0 0 0" rpy=" 0 0 0"/>
      <inertia
          ixx="0" ixy="0" ixz="0"
          iyy="0" iyz="0"
          izz="0"
      />
    </inertial>
  </link>

  <joint name="leftwheel_chasis" type="revolute">
    <origin rpy="0 0 0" xyz="0 0.323 0"/>
    <parent link="chasis"/>
    <child link="leftwheel"/>
    <axis xyz="0 0 1" />
    <limit upper="1.57" lower="-1.57" velocity="100" effort="1"/>
    <dynamics damping="${damping_value}" friction="${friction_value}"/>
  </joint>

  

  

  <link name="leftwheel">
    <visual>
      <origin rpy="0.0 0 0" xyz="0 0.323 0"/>
      <geometry>
        <mesh filename="package://pothole_detector/meshes/wheels/tyre1.dae"/>
      </geometry>
    </visual>
    <inertial>
      <origin xyz="0 0.323 0" rpy="0 1.5707 1.5707"/>
      <mass value="5"/>
      <inertia
        ixx=".1" ixy="0.0" ixz="0.0"
        iyy=".1" iyz="0.0"
        izz=".1"/>
    </inertial>
  </link>


  <joint name="rightwheel_chasis" type="revolute">
    <origin rpy="0 0 0" xyz="0 -0.323 0"/>
    <parent link="chasis"/>
    <child link="rightwheel"/>
    <axis xyz="0 0 1" />
    <limit upper="1.57" lower="-1.57" velocity="100" effort="1"/>
    <dynamics damping="${damping_value}" friction="${friction_value}"/>
  </joint>

  

  

  <link name="rightwheel">
    <visual>
      <origin rpy="0.0 0 0" xyz="0 -0.323 0"/>
      <geometry>
        <mesh filename="package://pothole_detector/meshes/wheels/tyre1.dae"/>
      </geometry>
    </visual>
    <inertial>
      <origin xyz="0 -0.323 0" rpy="0 1.5707 1.5707"/>
      <mass value="5"/>
      <inertia
        ixx=".1" ixy="0.0" ixz="0.0"
        iyy=".1" iyz="0.0"
        izz=".1"/>
    </inertial>
  </link>



  <joint name="castorwheel_chasis" type="revolute">
    <origin rpy="0 0 0" xyz="0.48 0 0.02"/>
    <parent link="chasis"/>
    <child link="castor_wheel"/>
    <axis xyz="0 0 1" />
    <limit upper="1.57" lower="-1.57" velocity="100" effort="1"/>
    <dynamics damping="${damping_value}" friction="${friction_value}"/>
  </joint>


  <link name="castor_wheel">
    <visual>
      <origin rpy="0.0 0 0" xyz="0.48 0 0.02" />
      <geometry>
        <mesh filename="package://pothole_detector/meshes/wheels/castors1.dae"/>
      </geometry>
    </visual>
    <inertial>
      <origin xyz="0.48 0 0.02" rpy="0 1.5707 1.5707"/>
      <mass value="3"/>
      <inertia
        ixx=".1" ixy="0.0" ixz="0.0"
        iyy=".1" iyz="0.0"
        izz=".1"/>
    </inertial>
  </link>

  
  <xacro:property name="camera_link" value="0.05" /> <!-- Size of square 'camera' box -->

  <joint name="camera_joint" type="fixed">
    <axis xyz="0 1 0" />
    <origin xyz="0.73 0 1.18" rpy="0 0.45 0"/>
    <parent link="chasis"/>
    <child link="camera_link"/>
    
  </joint>

  <!-- Camera -->
  <link name="camera_link">
    <collision>
      <origin xyz="0.73 0 1.18" rpy="0 0.45 0"/>
      <geometry>
    <box size="${camera_link} ${camera_link} ${camera_link}"/>
      </geometry>
    </collision>

    <visual>
      <origin xyz="0.73 0 1.18" rpy="0 0.45 0"/>
      <geometry>
    <box size="${camera_link} ${camera_link} ${camera_link}"/>
      </geometry>
      <material name="red"/>
    </visual>

    <!-- <inertial>
      <mass value="1e-5" />
      <origin xyz="0.73 0 1.18" rpy="0 0.45 0"/>
      <inertia ixx="1e-6" ixy="0" ixz="0" iyy="1e-6" iyz="0" izz="1e-6" />
    </inertial> -->
  </link>
</robot>